<?xml version="1.0"?>
<!--
  D.R.O.N.A. simulated humanoid (upper body) - ROS2 Humble.

  Head + torso + a 6-DOF right arm. Joint names mirror
  drona.interaction.demonstration.JOINT_NAMES so /drona/joint_states drives this
  model unchanged in RViz / Gazebo / Isaac. Geometry uses primitives (no mesh
  assets) and approximate SO-100-class link dimensions; inertials are provided so
  the model is valid in physics simulators.
-->
<robot xmlns:xacro="http://www.ros.org/wiki/xacro" name="drona_humanoid">

  <!-- ── Materials ─────────────────────────────────────────────────────────── -->
  <material name="drona_crimson"><color rgba="0.78 0.10 0.23 1.0"/></material>
  <material name="drona_slate"><color rgba="0.25 0.28 0.34 1.0"/></material>
  <material name="drona_green"><color rgba="0.30 0.80 0.30 1.0"/></material>
  <material name="drona_red"><color rgba="0.80 0.30 0.30 1.0"/></material>
  <material name="drona_yellow"><color rgba="0.85 0.80 0.30 1.0"/></material>
  <material name="drona_blue"><color rgba="0.35 0.45 0.90 1.0"/></material>
  <material name="drona_skin"><color rgba="0.90 0.78 0.68 1.0"/></material>

  <!-- Reusable inertial macro (small solid-ish box approximation). -->
  <xacro:macro name="box_inertial" params="mass">
    <inertial>
      <mass value="${mass}"/>
      <inertia ixx="${mass*0.002}" ixy="0" ixz="0"
               iyy="${mass*0.002}" iyz="0" izz="${mass*0.002}"/>
    </inertial>
  </xacro:macro>

  <!-- ── Torso (root) ──────────────────────────────────────────────────────── -->
  <link name="base_link">
    <visual>
      <origin xyz="0 0 0.20"/>
      <geometry><box size="0.22 0.14 0.40"/></geometry>
      <material name="drona_slate"/>
    </visual>
    <collision>
      <origin xyz="0 0 0.20"/>
      <geometry><box size="0.22 0.14 0.40"/></geometry>
    </collision>
    <xacro:box_inertial mass="2.0"/>
  </link>

  <!-- Head (fixed) -->
  <link name="head_link">
    <visual>
      <geometry><sphere radius="0.09"/></geometry>
      <material name="drona_skin"/>
    </visual>
    <collision><geometry><sphere radius="0.09"/></geometry></collision>
    <xacro:box_inertial mass="0.6"/>
  </link>
  <joint name="neck_fixed" type="fixed">
    <parent link="base_link"/>
    <child link="head_link"/>
    <origin xyz="0 0 0.50"/>
  </joint>

  <!-- Shoulder mount (fixed offset to the right shoulder) -->
  <link name="arm_base">
    <visual>
      <geometry><cylinder radius="0.04" length="0.05"/></geometry>
      <material name="drona_crimson"/>
    </visual>
    <collision><geometry><cylinder radius="0.04" length="0.05"/></geometry></collision>
    <xacro:box_inertial mass="0.5"/>
  </link>
  <joint name="shoulder_fixed" type="fixed">
    <parent link="base_link"/>
    <child link="arm_base"/>
    <origin xyz="0 -0.13 0.36"/>
  </joint>

  <!-- ── j0: base yaw ─────────────────────────────────────────────────────── -->
  <link name="shoulder_link">
    <visual>
      <geometry><cylinder radius="0.035" length="0.04"/></geometry>
      <material name="drona_crimson"/>
    </visual>
    <collision><geometry><cylinder radius="0.035" length="0.04"/></geometry></collision>
    <xacro:box_inertial mass="0.3"/>
  </link>
  <joint name="j0_base_yaw" type="revolute">
    <parent link="arm_base"/>
    <child link="shoulder_link"/>
    <origin xyz="0 0 0.04"/>
    <axis xyz="0 0 1"/>
    <limit lower="-3.1416" upper="3.1416" effort="10" velocity="3.0"/>
  </joint>

  <!-- ── j1: shoulder pitch ───────────────────────────────────────────────── -->
  <link name="upper_arm">
    <visual>
      <origin xyz="0 0 0.075"/>
      <geometry><cylinder radius="0.025" length="0.15"/></geometry>
      <material name="drona_green"/>
    </visual>
    <collision>
      <origin xyz="0 0 0.075"/>
      <geometry><cylinder radius="0.025" length="0.15"/></geometry>
    </collision>
    <xacro:box_inertial mass="0.3"/>
  </link>
  <joint name="j1_shoulder" type="revolute">
    <parent link="shoulder_link"/>
    <child link="upper_arm"/>
    <origin xyz="0 0 0.02"/>
    <axis xyz="0 1 0"/>
    <limit lower="-1.5708" upper="1.5708" effort="10" velocity="3.0"/>
  </joint>

  <!-- ── j2: elbow ────────────────────────────────────────────────────────── -->
  <link name="forearm">
    <visual>
      <origin xyz="0 0 0.06"/>
      <geometry><cylinder radius="0.02" length="0.12"/></geometry>
      <material name="drona_red"/>
    </visual>
    <collision>
      <origin xyz="0 0 0.06"/>
      <geometry><cylinder radius="0.02" length="0.12"/></geometry>
    </collision>
    <xacro:box_inertial mass="0.2"/>
  </link>
  <joint name="j2_elbow" type="revolute">
    <parent link="upper_arm"/>
    <child link="forearm"/>
    <origin xyz="0 0 0.15"/>
    <axis xyz="0 1 0"/>
    <limit lower="-3.1416" upper="3.1416" effort="8" velocity="3.0"/>
  </joint>

  <!-- ── j3: wrist pitch ──────────────────────────────────────────────────── -->
  <link name="wrist_pitch_link">
    <visual>
      <origin xyz="0 0 0.035"/>
      <geometry><cylinder radius="0.015" length="0.07"/></geometry>
      <material name="drona_yellow"/>
    </visual>
    <collision>
      <origin xyz="0 0 0.035"/>
      <geometry><cylinder radius="0.015" length="0.07"/></geometry>
    </collision>
    <xacro:box_inertial mass="0.1"/>
  </link>
  <joint name="j3_wrist_pitch" type="revolute">
    <parent link="forearm"/>
    <child link="wrist_pitch_link"/>
    <origin xyz="0 0 0.12"/>
    <axis xyz="0 1 0"/>
    <limit lower="-1.5708" upper="1.5708" effort="5" velocity="3.0"/>
  </joint>

  <!-- ── j4: wrist roll ───────────────────────────────────────────────────── -->
  <link name="wrist_roll_link">
    <visual>
      <origin xyz="0 0 0.02"/>
      <geometry><cylinder radius="0.012" length="0.04"/></geometry>
      <material name="drona_blue"/>
    </visual>
    <collision>
      <origin xyz="0 0 0.02"/>
      <geometry><cylinder radius="0.012" length="0.04"/></geometry>
    </collision>
    <xacro:box_inertial mass="0.05"/>
  </link>
  <joint name="j4_wrist_roll" type="revolute">
    <parent link="wrist_pitch_link"/>
    <child link="wrist_roll_link"/>
    <origin xyz="0 0 0.07"/>
    <axis xyz="0 0 1"/>
    <limit lower="-3.1416" upper="3.1416" effort="5" velocity="3.0"/>
  </joint>

  <!-- ── j5: gripper (prismatic) ──────────────────────────────────────────── -->
  <link name="gripper_link">
    <visual>
      <geometry><box size="0.03 0.02 0.02"/></geometry>
      <material name="drona_crimson"/>
    </visual>
    <collision><geometry><box size="0.03 0.02 0.02"/></geometry></collision>
    <xacro:box_inertial mass="0.02"/>
  </link>
  <joint name="j5_gripper" type="prismatic">
    <parent link="wrist_roll_link"/>
    <child link="gripper_link"/>
    <origin xyz="0 0 0.04"/>
    <axis xyz="1 0 0"/>
    <limit lower="0.0" upper="1.0" effort="3" velocity="1.0"/>
  </joint>

</robot>
